Workbook

Sheet Team
B1: id | C1: name | D1: conference_id | H1: id
A2: Celtics | B2: 1 | C2: Boston Celtics | D2: =VLOOKUP(G2,Conference!C:D,2,FALSE) -> 1 | E2: Celtics | F2: East | G2: Atlantic | H2: 1
A3: Nets | B3: 2 | C3: Brooklyn Nets | D3: =VLOOKUP(G3,Conference!C:D,2,FALSE) -> 1 | E3: Nets | F3: East | G3: Atlantic | H3: 2
A4: Knicks | B4: 3 | C4: New York Knicks | D4: =VLOOKUP(G4,Conference!C:D,2,FALSE) -> 1 | E4: Knicks | F4: East | G4: Atlantic | H4: 3
A5: 76ers | B5: 4 | C5: Philadelphia 76ers | D5: =VLOOKUP(G5,Conference!C:D,2,FALSE) -> 1 | E5: 76ers | F5: East | G5: Atlantic | H5: 4
A6: Raptors | B6: 5 | C6: Toronto Raptors | D6: =VLOOKUP(G6,Conference!C:D,2,FALSE) -> 1 | E6: Raptors | F6: East | G6: Atlantic | H6: 5
A7: Bulls | B7: 6 | C7: Chicago Bulls | D7: =VLOOKUP(G7,Conference!C:D,2,FALSE) -> 2 | E7: Bulls | F7: East | G7: Central | H7: 6
A8: Cavaliers | B8: 7 | C8: Cleveland Cavaliers | D8: =VLOOKUP(G8,Conference!C:D,2,FALSE) -> 2 | E8: Cavaliers | F8: East | G8: Central | H8: 7
A9: Pistons | B9: 8 | C9: Detroit Pistons | D9: =VLOOKUP(G9,Conference!C:D,2,FALSE) -> 2 | E9: Pistons | F9: East | G9: Central | H9: 8
A10: Pacers | B10: 9 | C10: Indiana Pacers | D10: =VLOOKUP(G10,Conference!C:D,2,FALSE) -> 2 | E10: Pacers | F10: East | G10: Central | H10: 9
A11: Bucks | B11: 10 | C11: Milwaukee Bucks | D11: =VLOOKUP(G11,Conference!C:D,2,FALSE) -> 2 | E11: Bucks | F11: East | G11: Central | H11: 10
A12: Hawks | B12: 11 | C12: Atlanta Hawks | D12: =VLOOKUP(G12,Conference!C:D,2,FALSE) -> 3 | E12: Hawks | F12: East | G12: Southeast | H12: 11
A13: Hornets | B13: 12 | C13: Charlotte Hornets | D13: =VLOOKUP(G13,Conference!C:D,2,FALSE) -> 3 | E13: Hornets | F13: East | G13: Southeast | H13: 12
... A31: Spurs | B31: 30 | C31: San Antonio Spurs | D31: =VLOOKUP(G31,Conference!C:D,2,FALSE) -> 6 | E31: Spurs | F31: West | G31: Southwest | H31: 30

Sheet Team_position
A1: id | B1: team_id | C1: position | D1: season_id
A2: 1 | B2: 1 | C2: 2 | D2: 1
A3: 2 | B3: 2 | C3: 6 | D3: 1
A4: 3 | B4: 3 | C4: 5 | D4: 1
A5: 4 | B5: 4 | C5: 3 | D5: 1
A6: 5 | B6: 5 | C6: 9 | D6: 1
A7: 6 | B7: 6 | C7: 10 | D7: 1
A8: 7 | B8: 7 | C8: 4 | D8: 1
A9: 8 | B9: 8 | C9: 15 | D9: 1
A10: 9 | B10: 9 | C10: 12 | D10: 1
A11: 10 | B11: 10 | C11: 1 | D11: 1
A12: 11 | B12: 11 | C12: 8 | D12: 1
A13: 12 | B13: 12 | C13: 14 | D13: 1
... A31: 30 | B31: 30 | C31: 14 | D31: 1

Sheet Player
A1: id | B1: team_id | C1: name | D1: id
A2: 1 | B2: =VLOOKUP(K2,Team!A:B,2,FALSE) -> 11 | C2: Dejounte Murray | D2: 1 | K2: Hawks
A3: 2 | B3: =VLOOKUP(K3,Team!A:B,2,FALSE) -> 11 | C3: Trae Young | D3: 2 | K3: Hawks
A4: 3 | B4: =VLOOKUP(K4,Team!A:B,2,FALSE) -> 11 | C4: De'Andre Hunter | D4: 3 | K4: Hawks
A5: 4 | B5: =VLOOKUP(K5,Team!A:B,2,FALSE) -> 11 | C5: Saddiq Bey | D5: 4 | K5: Hawks
A6: 5 | B6: =VLOOKUP(K6,Team!A:B,2,FALSE) -> 11 | C6: John Collins | D6: 5 | K6: Hawks
A7: 6 | B7: =VLOOKUP(K7,Team!A:B,2,FALSE) -> 2 | C7: Mikal Bridges | D7: 6 | K7: Nets
A8: 7 | B8: =VLOOKUP(K8,Team!A:B,2,FALSE) -> 2 | C8: Spencer Dinwiddie | D8: 7 | K8: Nets
A9: 8 | B9: =VLOOKUP(K9,Team!A:B,2,FALSE) -> 2 | C9: Royce O'Neale | D9: 8 | K9: Nets
A10: 9 | B10: =VLOOKUP(K10,Team!A:B,2,FALSE) -> 2 | C10: Dorian Finney-Smith | D10: 9 | K10: Nets
A11: 10 | B11: =VLOOKUP(K11,Team!A:B,2,FALSE) -> 2 | C11: Nic Claxton | D11: 10 | K11: Nets
A12: 11 | B12: =VLOOKUP(K12,Team!A:B,2,FALSE) -> 1 | C12: Jayson Tatum | D12: 11 | K12: Celtics
A13: 12 | B13: =VLOOKUP(K13,Team!A:B,2,FALSE) -> 1 | C13: Jaylen Brown | D13: 12 | K13: Celtics
... A151: 150 | B151: =VLOOKUP(K151,Team!A:B,2,FALSE) -> 15 | C151: Deni Avdija | D151: 150 | K151: Wizards

Sheet Player_point
A1: id | B1: player_id | C1: game_id | D1: three_point | E1: two_point | F1: free_point | G1: season_id
A2: 1 | B2: 111 | C2: 1 | D2: 2.8 | E2: 6.4 | F2: 5.4 | G2: 1 | H2: ="INSERT INTO player_point (id, player_id, game_id, three_point, two_point, free_point, season_id) VALUES (" & A2 & ", " & B2 & ", " & C2 & ", " & D2 & ", " & E2 & ", " & F2 & ", " & G2 & ");" -> INSERT INTO player_point (id, player_id, game_id, three_point, two_point, free_point, season_id) VALUES (1, 111, 1, 2.8, 6.4, 5.4, 1);
A3: 2 | B3: 112 | C3: 1 | D3: 2.7 | E3: 7.3 | F3: 3 | G3: 1 | H3: ="INSERT INTO player_point (id, player_id, game_id, three_point, two_point, free_point, season_id) VALUES (" & A3 & ", " & B3 & ", " & C3 & ", " & D3 & ", " & E3 & ", " & F3 & ", " & G3 & ");" -> INSERT INTO player_point (id, player_id, game_id, three_point, two_point, free_point, season_id) VALUES (2, 112, 1, 2.7, 7.3, 3, 1);
A4: 3 | B4: 113 | C4: 1 | D4: 1 | E4: 11 | F4: 10 | G4: 1 | H4: ="INSERT INTO player_point (id, player_id, game_id, three_point, two_point, free_point, season_id) VALUES (" & A4 & ", " & B4 & ", " & C4 & ", " & D4 & ", " & E4 & ", " & F4 & ", " & G4 & ");" -> INSERT INTO player_point (id, player_id, game_id, three_point, two_point, free_point, season_id) VALUES (3, 113, 1, 1, 11, 10, 1);
A5: 4 | B5: 114 | C5: 1 | D5: 2 | E5: 3.6 | F5: 0.9 | G5: 1 | H5: ="INSERT INTO player_point (id, player_id, game_id, three_point, two_point, free_point, season_id) VALUES (" & A5 & ", " & B5 & ", " & C5 & ", " & D5 & ", " & E5 & ", " & F5 & ", " & G5 & ");" -> INSERT INTO player_point (id, player_id, game_id, three_point, two_point, free_point, season_id) VALUES (4, 114, 1, 2, 3.6, 0.9, 1);
A6: 5 | B6: 115 | C6: 1 | D6: 1.7 | E6: 5.7 | F6: 1.5 | G6: 1 | H6: ="INSERT INTO player_point (id, player_id, game_id, three_point, two_point, free_point, season_id) VALUES (" & A6 & ", " & B6 & ", " & C6 & ", " & D6 & ", " & E6 & ", " & F6 & ", " & G6 & ");" -> INSERT INTO player_point (id, player_id, game_id, three_point, two_point, free_point, season_id) VALUES (5, 115, 1, 1.7, 5.7, 1.5, 1);
A7: 6 | B7: 111 | C7: 15 | D7: 2.8 | E7: 6.4 | F7: 5.4 | G7: 1 | H7: ="INSERT INTO player_point (id, player_id, game_id, three_point, two_point, free_point, season_id) VALUES (" & A7 & ", " & B7 & ", " & C7 & ", " & D7 & ", " & E7 & ", " & F7 & ", " & G7 & ");" -> INSERT INTO player_point (id, player_id, game_id, three_point, two_point, free_point, season_id) VALUES (6, 111, 15, 2.8, 6.4, 5.4, 1);
A8: 7 | B8: 112 | C8: 15 | D8: 2.7 | E8: 7.3 | F8: 3 | G8: 1 | H8: ="INSERT INTO player_point (id, player_id, game_id, three_point, two_point, free_point, season_id) VALUES (" & A8 & ", " & B8 & ", " & C8 & ", " & D8 & ", " & E8 & ", " & F8 & ", " & G8 & ");" -> INSERT INTO player_point (id, player_id, game_id, three_point, two_point, free_point, season_id) VALUES (7, 112, 15, 2.7, 7.3, 3, 1);
A9: 8 | B9: 113 | C9: 15 | D9: 1 | E9: 11 | F9: 10 | G9: 1 | H9: ="INSERT INTO player_point (id, player_id, game_id, three_point, two_point, free_point, season_id) VALUES (" & A9 & ", " & B9 & ", " & C9 & ", " & D9 & ", " & E9 & ", " & F9 & ", " & G9 & ");" -> INSERT INTO player_point (id, player_id, game_id, three_point, two_point, free_point, season_id) VALUES (8, 113, 15, 1, 11, 10, 1);
A10: 9 | B10: 114 | C10: 15 | D10: 2 | E10: 3.6 | F10: 0.9 | G10: 1 | H10: ="INSERT INTO player_point (id, player_id, game_id, three_point, two_point, free_point, season_id) VALUES (" & A10 & ", " & B10 & ", " & C10 & ", " & D10 & ", " & E10 & ", " & F10 & ", " & G10 & ");" -> INSERT INTO player_point (id, player_id, game_id, three_point, two_point, free_point, season_id) VALUES (9, 114, 15, 2, 3.6, 0.9, 1);
A11: 10 | B11: 115 | C11: 15 | D11: 1.7 | E11: 5.7 | F11: 1.5 | G11: 1 | H11: ="INSERT INTO player_point (id, player_id, game_id, three_point, two_point, free_point, season_id) VALUES (" & A11 & ", " & B11 & ", " & C11 & ", " & D11 & ", " & E11 & ", " & F11 & ", " & G11 & ");" -> INSERT INTO player_point (id, player_id, game_id, three_point, two_point, free_point, season_id) VALUES (10, 115, 15, 1.7, 5.7, 1.5, 1);
A12: 11 | B12: 111 | C12: 28 | D12: 2.8 | E12: 6.4 | F12: 5.4 | G12: 1 | H12: ="INSERT INTO player_point (id, player_id, game_id, three_point, two_point, free_point, season_id) VALUES (" & A12 & ", " & B12 & ", " & C12 & ", " & D12 & ", " & E12 & ", " & F12 & ", " & G12 & ");" -> INSERT INTO player_point (id, player_id, game_id, three_point, two_point, free_point, season_id) VALUES (11, 111, 28, 2.8, 6.4, 5.4, 1);
A13: 12 | B13: 112 | C13: 28 | D13: 2.7 | E13: 7.3 | F13: 3 | G13: 1 | H13: ="INSERT INTO player_point (id, player_id, game_id, three_point, two_point, free_point, season_id) VALUES (" & A13 & ", " & B13 & ", " & C13 & ", " & D13 & ", " & E13 & ", " & F13 & ", " & G13 & ");" -> INSERT INTO player_point (id, player_id, game_id, three_point, two_point, free_point, season_id) VALUES (12, 112, 28, 2.7, 7.3, 3, 1);
... A370: 369 | B370: 80 | C370: 32 | D370: 2.5 | E370: 4.1 | F370: 1 | G370: 1 | H370: ="INSERT INTO player_point (id, player_id, game_id, three_point, two_point, free_point, season_id) VALUES (" & A370 & ", " & B370 & ", " & C370 & ", " & D370 & ", " & E370 & ", " & F370 & ", " & G370 & ");" -> INSERT INTO player_point (id, player_id, game_id, three_point, two_point, free_point, season_id) VALUES (369, 80, 32, 2.5, 4.1, 1, 1);
A371: 370 | B371: 76 | C371: No encontrado | D371: 3 | E371: 7.3 | F371: 2.5 | G371: 1 | H371: ="INSERT INTO player_point (id, player_id, game_id, three_point, two_point, free_point, season_id) VALUES (" & A371 & ", " & B371 & ", " & C371 & ", " & D371 & ", " & E371 & ", " & F371 & ", " & G371 & ");" -> INSERT INTO player_point (id, player_id, game_id, three_point, two_point, free_point, season_id) VALUES (370, 76, No encontrado, 3, 7.3, 2.5, 1);
A372: 371 | B372: 77 | C372: No encontrado | D372: 0 | E372: 8 | F372: 4.3 | G372: 1 | H372: ="INSERT INTO player_point (id, player_id, game_id, three_point, two_point, free_point, season_id) VALUES (" & A372 & ", " & B372 & ", " & C372 & ", " & D372 & ", " & E372 & ", " & F372 & ", " & G372 & ");" -> INSERT INTO player_point (id, player_id, game_id, three_point, two_point, free_point, season_id) VALUES (371, 77, No encontrado, 0, 8, 4.3, 1);
A373: 372 | B373: 78 | C373: No encontrado | D373: 0.6 | E373: 7.5 | F373: 7.4 | G373: 1 | H373: ="INSERT INTO player_point (id, player_id, game_id, three_point, two_point, free_point, season_id) VALUES (" & A373 & ", " & B373 & ", " & C373 & ", " & D373 & ", " & E373 & ", " & F373 & ", " & G373 & ");" -> INSERT INTO player_point (id, player_id, game_id, three_point, two_point, free_point, season_id) VALUES (372, 78, No encontrado, 0.6, 7.5, 7.4, 1);
A374: 373 | B374: 79 | C374: No encontrado | D374: 1.2 | E374: 3.6 | F374: 1.3 | G374: 1 | H374: ="INSERT INTO player_point (id, player_id, game_id, three_point, two_point, free_point, season_id) VALUES (" & A374 & ", " & B374 & ", " & C374 & ", " & D374 & ", " & E374 & ", " & F374 & ", " & G374 & ");" -> INSERT INTO player_point (id, player_id, game_id, three_point, two_point, free_point, season_id) VALUES (373, 79, No encontrado, 1.2, 3.6, 1.3, 1);
A375: 374 | B375: 80 | C375: No encontrado | D375: 2.5 | E375: 4.1 | F375: 1 | G375: 1 | H375: ="INSERT INTO player_point (id, player_id, game_id, three_point, two_point, free_point, season_id) VALUES (" & A375 & ", " & B375 & ", " & C375 & ", " & D375 & ", " & E375 & ", " & F375 & ", " & G375 & ");" -> INSERT INTO player_point (id, player_id, game_id, three_point, two_point, free_point, season_id) VALUES (374, 80, No encontrado, 2.5, 4.1, 1, 1);
A376: 375 | B376: 76 | C376: No encontrado | D376: 3 | E376: 7.3 | F376: 2.5 | G376: 1 | H376: ="INSERT INTO player_point (id, player_id, game_id, three_point, two_point, free_point, season_id) VALUES (" & A376 & ", " & B376 & ", " & C376 & ", " & D376 & ", " & E376 & ", " & F376 & ", " & G376 & ");" -> INSERT INTO player_point (id, player_id, game_id, three_point, two_point, free_point, season_id) VALUES (375, 76, No encontrado, 3, 7.3, 2.5, 1);
A377: 376 | B377: 77 | C377: No encontrado | D377: 0 | E377: 8 | F377: 4.3 | G377: 1 | H377: ="INSERT INTO player_point (id, player_id, game_id, three_point, two_point, free_point, season_id) VALUES (" & A377 & ", " & B377 & ", " & C377 & ", " & D377 & ", " & E377 & ", " & F377 & ", " & G377 & ");" -> INSERT INTO player_point (id, player_id, game_id, three_point, two_point, free_point, season_id) VALUES (376, 77, No encontrado, 0, 8, 4.3, 1);
A378: 377 | B378: 78 | C378: No encontrado | D378: 0.6 | E378: 7.5 | F378: 7.4 | G378: 1 | H378: ="INSERT INTO player_point (id, player_id, game_id, three_point, two_point, free_point, season_id) VALUES (" & A378 & ", " & B378 & ", " & C378 & ", " & D378 & ", " & E378 & ", " & F378 & ", " & G378 & ");" -> INSERT INTO player_point (id, player_id, game_id, three_point, two_point, free_point, season_id) VALUES (377, 78, No encontrado, 0.6, 7.5, 7.4, 1);
A379: 378 | B379: 79 | C379: No encontrado | D379: 1.2 | E379: 3.6 | F379: 1.3 | G379: 1 | H379: ="INSERT INTO player_point (id, player_id, game_id, three_point, two_point, free_point, season_id) VALUES (" & A379 & ", " & B379 & ", " & C379 & ", " & D379 & ", " & E379 & ", " & F379 & ", " & G379 & ");" -> INSERT INTO player_point (id, player_id, game_id, three_point, two_point, free_point, season_id) VALUES (378, 79, No encontrado, 1.2, 3.6, 1.3, 1);
A380: 379 | B380: 80 | C380: No encontrado | D380: 2.5 | E380: 4.1 | F380: 1 | G380: 1 | H380: ="INSERT INTO player_point (id, player_id, game_id, three_point, two_point, free_point, season_id) VALUES (" & A380 & ", " & B380 & ", " & C380 & ", " & D380 & ", " & E380 & ", " & F380 & ", " & G380 & ");" -> INSERT INTO player_point (id, player_id, game_id, three_point, two_point, free_point, season_id) VALUES (379, 80, No encontrado, 2.5, 4.1, 1, 1);
A381: 380 | B381: 76 | C381: 64 | D381: 3 | E381: 7.3 | F381: 2.5 | G381: 1 | H381: ="INSERT INTO player_point (id, player_id, game_id, three_point, two_point, free_point, season_id) VALUES (" & A381 & ", " & B381 & ", " & C381 & ", " & D381 & ", " & E381 & ", " & F381 & ", " & G381 & ");" -> INSERT INTO player_point (id, player_id, game_id, three_point, two_point, free_point, season_id) VALUES (380, 76, 64, 3, 7.3, 2.5, 1);
A382: 381 | B382: 77 | C382: 64 | D382: 0 | E382: 8 | F382: 4.3 | G382: 1 | H382: ="INSERT INTO player_point (id, player_id, game_id, three_point, two_point, free_point, season_id) VALUES (" & A382 & ", " & B382 & ", " & C382 & ", " & D382 & ", " & E382 & ", " & F382 & ", " & G382 & ");" -> INSERT INTO player_point (id, player_id, game_id, three_point, two_point, free_point, season_id) VALUES (381, 77, 64, 0, 8, 4.3, 1);
A383: 382 | B383: 78 | C383: 64 | D383: 0.6 | E383: 7.5 | F383: 7.4 | G383: 1 | H383: ="INSERT INTO player_point (id, player_id, game_id, three_point, two_point, free_point, season_id) VALUES (" & A383 & ", " & B383 & ", " & C383 & ", " & D383 & ", " & E383 & ", " & F383 & ", " & G383 & ");" -> INSERT INTO player_point (id, player_id, game_id, three_point, two_point, free_point, season_id) VALUES (382, 78, 64, 0.6, 7.5, 7.4, 1);
A384: 383 | B384: 79 | C384: 64 | D384: 1.2 | E384: 3.6 | F384: 1.3 | G384: 1 | H384: ="INSERT INTO player_point (id, player_id, game_id, three_point, two_point, free_point, season_id) VALUES (" & A384 & ", " & B384 & ", " & C384 & ", " & D384 & ", " & E384 & ", " & F384 & ", " & G384 & ");" -> INSERT INTO player_point (id, player_id, game_id, three_point, two_point, free_point, season_id) VALUES (383, 79, 64, 1.2, 3.6, 1.3, 1);
A385: 384 | B385: 80 | C385: 64 | D385: 2.5 | E385: 4.1 | F385: 1 | G385: 1 | H385: ="INSERT INTO player_point (id, player_id, game_id, three_point, two_point, free_point, season_id) VALUES (" & A385 & ", " & B385 & ", " & C385 & ", " & D385 & ", " & E385 & ", " & F385 & ", " & G385 & ");" -> INSERT INTO player_point (id, player_id, game_id, three_point, two_point, free_point, season_id) VALUES (384, 80, 64, 2.5, 4.1, 1, 1);
A386: 385 | B386: 76 | C386: 69 | D386: 3 | E386: 7.3 | F386: 2.5 | G386: 1 | H386: ="INSERT INTO player_point (id, player_id, game_id, three_point, two_point, free_point, season_id) VALUES (" & A386 & ", " & B386 & ", " & C386 & ", " & D386 & ", " & E386 & ", " & F386 & ", " & G386 & ");" -> INSERT INTO player_point (id, player_id, game_id, three_point, two_point, free_point, season_id) VALUES (385, 76, 69, 3, 7.3, 2.5, 1);
A387: 386 | B387: 77 | C387: 69 | D387: 0 | E387: 8 | F387: 4.3 | G387: 1 | H387: ="INSERT INTO player_point (id, player_id, game_id, three_point, two_point, free_point, season_id) VALUES (" & A387 & ", " & B387 & ", " & C387 & ", " & D387 & ", " & E387 & ", " & F387 & ", " & G387 & ");" -> INSERT INTO player_point (id, player_id, game_id, three_point, two_point, free_point, season_id) VALUES (386, 77, 69, 0, 8, 4.3, 1);
A388: 387 | B388: 78 | C388: 69 | D388: 0.6 | E388: 7.5 | F388: 7.4 | G388: 1 | H388: ="INSERT INTO player_point (id, player_id, game_id, three_point, two_point, free_point, season_id) VALUES (" & A388 & ", " & B388 & ", " & C388 & ", " & D388 & ", " & E388 & ", " & F388 & ", " & G388 & ");" -> INSERT INTO player_point (id, player_id, game_id, three_point, two_point, free_point, season_id) VALUES (387, 78, 69, 0.6, 7.5, 7.4, 1);
A389: 388 | B389: 79 | C389: 69 | D389: 1.2 | E389: 3.6 | F389: 1.3 | G389: 1 | H389: ="INSERT INTO player_point (id, player_id, game_id, three_point, two_point, free_point, season_id) VALUES (" & A389 & ", " & B389 & ", " & C389 & ", " & D389 & ", " & E389 & ", " & F389 & ", " & G389 & ");" -> INSERT INTO player_point (id, player_id, game_id, three_point, two_point, free_point, season_id) VALUES (388, 79, 69, 1.2, 3.6, 1.3, 1);
A390: 389 | B390: 80 | C390: 69 | D390: 2.5 | E390: 4.1 | F390: 1 | G390: 1 | H390: ="INSERT INTO player_point (id, player_id, game_id, three_point, two_point, free_point, season_id) VALUES (" & A390 & ", " & B390 & ", " & C390 & ", " & D390 & ", " & E390 & ", " & F390 & ", " & G390 & ");" -> INSERT INTO player_point (id, player_id, game_id, three_point, two_point, free_point, season_id) VALUES (389, 80, 69, 2.5, 4.1, 1, 1);
A391: 390 | B391: 76 | C391: 81 | D391: 3 | E391: 7.3 | F391: 2.5 | G391: 1 | H391: ="INSERT INTO player_point (id, player_id, game_id, three_point, two_point, free_point, season_id) VALUES (" & A391 & ", " & B391 & ", " & C391 & ", " & D391 & ", " & E391 & ", " & F391 & ", " & G391 & ");" -> INSERT INTO player_point (id, player_id, game_id, three_point, two_point, free_point, season_id) VALUES (390, 76, 81, 3, 7.3, 2.5, 1);
A392: 391 | B392: 77 | C392: 81 | D392: 0 | E392: 8 | F392: 4.3 | G392: 1 | H392: ="INSERT INTO player_point (id, player_id, game_id, three_point, two_point, free_point, season_id) VALUES (" & A392 & ", " & B392 & ", " & C392 & ", " & D392 & ", " & E392 & ", " & F392 & ", " & G392 & ");" -> INSERT INTO player_point (id, player_id, game_id, three_point, two_point, free_point, season_id) VALUES (391, 77, 81, 0, 8, 4.3, 1);
... A984: 983 | B984: 85 | C984: 100 | D984: 1.4 | E984: 5.7 | F984: 1.4 | G984: 1 | H984: ="INSERT INTO player_point (id, player_id, game_id, three_point, two_point, free_point, season_id) VALUES (" & A984 & ", " & B984 & ", " & C984 & ", " & D984 & ", " & E984 & ", " & F984 & ", " & G984 & ");" -> INSERT INTO player_point (id, player_id, game_id, three_point, two_point, free_point, season_id) VALUES (983, 85, 100, 1.4, 5.7, 1.4, 1);

Sheet Player_fault
A1: id | B1: player_id | C1: game_id | D1: fault_id
A2: 1 | B2: 112 | C2: 1 | D2: 3 | E2: ="INSERT INTO player_fault (id, player_id, game_id, fault_id) VALUES (" & A2 & ", " & B2 & ", " & C2 & ", " & D2 & ");" -> INSERT INTO player_fault (id, player_id, game_id, fault_id) VALUES (1, 112, 1, 3);
A3: 2 | B3: 115 | C3: 1 | D3: 3 | E3: ="INSERT INTO player_fault (id, player_id, game_id, fault_id) VALUES (" & A3 & ", " & B3 & ", " & C3 & ", " & D3 & ");" -> INSERT INTO player_fault (id, player_id, game_id, fault_id) VALUES (2, 115, 1, 3);
A4: 3 | B4: 111 | C4: 15 | D4: 1 | E4: ="INSERT INTO player_fault (id, player_id, game_id, fault_id) VALUES (" & A4 & ", " & B4 & ", " & C4 & ", " & D4 & ");" -> INSERT INTO player_fault (id, player_id, game_id, fault_id) VALUES (3, 111, 15, 1);
A5: 4 | B5: 111 | C5: 28 | D5: 3 | E5: ="INSERT INTO player_fault (id, player_id, game_id, fault_id) VALUES (" & A5 & ", " & B5 & ", " & C5 & ", " & D5 & ");" -> INSERT INTO player_fault (id, player_id, game_id, fault_id) VALUES (4, 111, 28, 3);
A6: 5 | B6: 111 | C6: 44 | D6: 2 | E6: ="INSERT INTO player_fault (id, player_id, game_id, fault_id) VALUES (" & A6 & ", " & B6 & ", " & C6 & ", " & D6 & ");" -> INSERT INTO player_fault (id, player_id, game_id, fault_id) VALUES (5, 111, 44, 2);
A7: 6 | B7: 112 | C7: 44 | D7: 3 | E7: ="INSERT INTO player_fault (id, player_id, game_id, fault_id) VALUES (" & A7 & ", " & B7 & ", " & C7 & ", " & D7 & ");" -> INSERT INTO player_fault (id, player_id, game_id, fault_id) VALUES (6, 112, 44, 3);
A8: 7 | B8: 114 | C8: 44 | D8: 1 | E8: ="INSERT INTO player_fault (id, player_id, game_id, fault_id) VALUES (" & A8 & ", " & B8 & ", " & C8 & ", " & D8 & ");" -> INSERT INTO player_fault (id, player_id, game_id, fault_id) VALUES (7, 114, 44, 1);
A9: 8 | B9: 112 | C9: 60 | D9: 3 | E9: ="INSERT INTO player_fault (id, player_id, game_id, fault_id) VALUES (" & A9 & ", " & B9 & ", " & C9 & ", " & D9 & ");" -> INSERT INTO player_fault (id, player_id, game_id, fault_id) VALUES (8, 112, 60, 3);
A10: 9 | B10: 115 | C10: 60 | D10: 2 | E10: ="INSERT INTO player_fault (id, player_id, game_id, fault_id) VALUES (" & A10 & ", " & B10 & ", " & C10 & ", " & D10 & ");" -> INSERT INTO player_fault (id, player_id, game_id, fault_id) VALUES (9, 115, 60, 2);
A11: 10 | B11: 111 | C11: 60 | D11: 2 | E11: ="INSERT INTO player_fault (id, player_id, game_id, fault_id) VALUES (" & A11 & ", " & B11 & ", " & C11 & ", " & D11 & ");" -> INSERT INTO player_fault (id, player_id, game_id, fault_id) VALUES (10, 111, 60, 2);
A12: 11 | B12: 113 | C12: 60 | D12: 3 | E12: ="INSERT INTO player_fault (id, player_id, game_id, fault_id) VALUES (" & A12 & ", " & B12 & ", " & C12 & ", " & D12 & ");" -> INSERT INTO player_fault (id, player_id, game_id, fault_id) VALUES (11, 113, 60, 3);
A13: 12 | B13: 113 | C13: 96 | D13: 3 | E13: ="INSERT INTO player_fault (id, player_id, game_id, fault_id) VALUES (" & A13 & ", " & B13 & ", " & C13 & ", " & D13 & ");" -> INSERT INTO player_fault (id, player_id, game_id, fault_id) VALUES (12, 113, 96, 3);
... A317: 316 | B317: 84 | C317: 100 | D317: 3 | E317: ="INSERT INTO player_fault (id, player_id, game_id, fault_id) VALUES (" & A317 & ", " & B317 & ", " & C317 & ", " & D317 & ");" -> INSERT INTO player_fault (id, player_id, game_id, fault_id) VALUES (316, 84, 100, 3);

Sheet Player_point_temp
J1: player_id | K1: game_id | L1: three_point | M1: two_point | N1: free_point
A2: 76ers | B2: James Harden | C2: 2.8 | D2: 6.4 | E2: 5.4 | F2: Celtics | H2: 1 | J2: =VLOOKUP(B2,Player!C:D,2,FALSE) -> 111 | K2: 1 | L2: 2.8 | M2: 6.4 | N2: 5.4
A3: 76ers | B3: Tyrese Maxey | C3: 2.7 | D3: 7.3 | E3: 3 | F3: Celtics | H3: 1 | J3: =VLOOKUP(B3,Player!C:D,2,FALSE) -> 112 | K3: 1 | L3: 2.7 | M3: 7.3 | N3: 3
A4: 76ers | B4: Joel Embiid | C4: 1 | D4: 11 | E4: 10 | F4: Celtics | H4: 1 | J4: =VLOOKUP(B4,Player!C:D,2,FALSE) -> 113 | K4: 1 | L4: 1 | M4: 11 | N4: 10
A5: 76ers | B5: De'Anthony Melton | C5: 2 | D5: 3.6 | E5: 0.9 | F5: Celtics | H5: 1 | J5: =VLOOKUP(B5,Player!C:D,2,FALSE) -> 114 | K5: 1 | L5: 2 | M5: 3.6 | N5: 0.9
A6: 76ers | B6: Tobias Harris | C6: 1.7 | D6: 5.7 | E6: 1.5 | F6: Celtics | H6: 1 | J6: =VLOOKUP(B6,Player!C:D,2,FALSE) -> 115 | K6: 1 | L6: 1.7 | M6: 5.7 | N6: 1.5
A7: 76ers | B7: James Harden | C7: 2.8 | D7: 6.4 | E7: 5.4 | F7: Bucks | H7: 15 | J7: =VLOOKUP(B7,Player!C:D,2,FALSE) -> 111 | K7: 15 | L7: 2.8 | M7: 6.4 | N7: 5.4
A8: 76ers | B8: Tyrese Maxey | C8: 2.7 | D8: 7.3 | E8: 3 | F8: Bucks | H8: 15 | J8: =VLOOKUP(B8,Player!C:D,2,FALSE) -> 112 | K8: 15 | L8: 2.7 | M8: 7.3 | N8: 3
A9: 76ers | B9: Joel Embiid | C9: 1 | D9: 11 | E9: 10 | F9: Bucks | H9: 15 | J9: =VLOOKUP(B9,Player!C:D,2,FALSE) -> 113 | K9: 15 | L9: 1 | M9: 11 | N9: 10
A10: 76ers | B10: De'Anthony Melton | C10: 2 | D10: 3.6 | E10: 0.9 | F10: Bucks | H10: 15 | J10: =VLOOKUP(B10,Player!C:D,2,FALSE) -> 114 | K10: 15 | L10: 2 | M10: 3.6 | N10: 0.9
A11: 76ers | B11: Tobias Harris | C11: 1.7 | D11: 5.7 | E11: 1.5 | F11: Bucks | H11: 15 | J11: =VLOOKUP(B11,Player!C:D,2,FALSE) -> 115 | K11: 15 | L11: 1.7 | M11: 5.7 | N11: 1.5
A12: 76ers | B12: James Harden | C12: 2.8 | D12: 6.4 | E12: 5.4 | F12: Spurs | H12: 28 | J12: =VLOOKUP(B12,Player!C:D,2,FALSE) -> 111 | K12: 28 | L12: 2.8 | M12: 6.4 | N12: 5.4
A13: 76ers | B13: Tyrese Maxey | C13: 2.7 | D13: 7.3 | E13: 3 | F13: Spurs | H13: 28 | J13: =VLOOKUP(B13,Player!C:D,2,FALSE) -> 112 | K13: 28 | L13: 2.7 | M13: 7.3 | N13: 3
... A370: Heat | B370: Max Strus | C370: 2.5 | D370: 4.1 | E370: 1 | F370: Raptors | H370: 32 | J370: =VLOOKUP(B370,Player!C:D,2,FALSE) -> 80 | K370: 32 | L370: 2.5 | M370: 4.1 | N370: 1
A371: Heat | B371: Tyler Herro | C371: 3 | D371: 7.3 | E371: 2.5 | F371: Raptors | H371: No encontrado | J371: =VLOOKUP(B371,Player!C:D,2,FALSE) -> 76 | K371: No encontrado | L371: 3 | M371: 7.3 | N371: 2.5
A372: Heat | B372: Bam Adebayo | C372: 0 | D372: 8 | E372: 4.3 | F372: Raptors | H372: No encontrado | J372: =VLOOKUP(B372,Player!C:D,2,FALSE) -> 77 | K372: No encontrado | L372: 0 | M372: 8 | N372: 4.3
A373: Heat | B373: Jimmy Butler III | C373: 0.6 | D373: 7.5 | E373: 7.4 | F373: Raptors | H373: No encontrado | J373: =VLOOKUP(B373,Player!C:D,2,FALSE) -> 78 | K373: No encontrado | L373: 0.6 | M373: 7.5 | N373: 7.4
A374: Heat | B374: Caleb Martin | C374: 1.2 | D374: 3.6 | E374: 1.3 | F374: Raptors | H374: No encontrado | J374: =VLOOKUP(B374,Player!C:D,2,FALSE) -> 79 | K374: No encontrado | L374: 1.2 | M374: 3.6 | N374: 1.3
A375: Heat | B375: Max Strus | C375: 2.5 | D375: 4.1 | E375: 1 | F375: Raptors | H375: No encontrado | J375: =VLOOKUP(B375,Player!C:D,2,FALSE) -> 80 | K375: No encontrado | L375: 2.5 | M375: 4.1 | N375: 1
A376: Heat | B376: Tyler Herro | C376: 3 | D376: 7.3 | E376: 2.5 | F376: Raptors | H376: No encontrado | J376: =VLOOKUP(B376,Player!C:D,2,FALSE) -> 76 | K376: No encontrado | L376: 3 | M376: 7.3 | N376: 2.5
A377: Heat | B377: Bam Adebayo | C377: 0 | D377: 8 | E377: 4.3 | F377: Raptors | H377: No encontrado | J377: =VLOOKUP(B377,Player!C:D,2,FALSE) -> 77 | K377: No encontrado | L377: 0 | M377: 8 | N377: 4.3
A378: Heat | B378: Jimmy Butler III | C378: 0.6 | D378: 7.5 | E378: 7.4 | F378: Raptors | H378: No encontrado | J378: =VLOOKUP(B378,Player!C:D,2,FALSE) -> 78 | K378: No encontrado | L378: 0.6 | M378: 7.5 | N378: 7.4
A379: Heat | B379: Caleb Martin | C379: 1.2 | D379: 3.6 | E379: 1.3 | F379: Raptors | H379: No encontrado | J379: =VLOOKUP(B379,Player!C:D,2,FALSE) -> 79 | K379: No encontrado | L379: 1.2 | M379: 3.6 | N379: 1.3
A380: Heat | B380: Max Strus | C380: 2.5 | D380: 4.1 | E380: 1 | F380: Raptors | H380: No encontrado | J380: =VLOOKUP(B380,Player!C:D,2,FALSE) -> 80 | K380: No encontrado | L380: 2.5 | M380: 4.1 | N380: 1
A381: Heat | B381: Tyler Herro | C381: 3 | D381: 7.3 | E381: 2.5 | F381: Trail Blazers | H381: 64 | J381: =VLOOKUP(B381,Player!C:D,2,FALSE) -> 76 | K381: 64 | L381: 3 | M381: 7.3 | N381: 2.5
A382: Heat | B382: Bam Adebayo | C382: 0 | D382: 8 | E382: 4.3 | F382: Trail Blazers | H382: 64 | J382: =VLOOKUP(B382,Player!C:D,2,FALSE) -> 77 | K382: 64 | L382: 0 | M382: 8 | N382: 4.3
A383: Heat | B383: Jimmy Butler III | C383: 0.6 | D383: 7.5 | E383: 7.4 | F383: Trail Blazers | H383: 64 | J383: =VLOOKUP(B383,Player!C:D,2,FALSE) -> 78 | K383: 64 | L383: 0.6 | M383: 7.5 | N383: 7.4
A384: Heat | B384: Caleb Martin | C384: 1.2 | D384: 3.6 | E384: 1.3 | F384: Trail Blazers | H384: 64 | J384: =VLOOKUP(B384,Player!C:D,2,FALSE) -> 79 | K384: 64 | L384: 1.2 | M384: 3.6 | N384: 1.3
A385: Heat | B385: Max Strus | C385: 2.5 | D385: 4.1 | E385: 1 | F385: Trail Blazers | H385: 64 | J385: =VLOOKUP(B385,Player!C:D,2,FALSE) -> 80 | K385: 64 | L385: 2.5 | M385: 4.1 | N385: 1
A386: Heat | B386: Tyler Herro | C386: 3 | D386: 7.3 | E386: 2.5 | F386: Warriors | H386: 69 | J386: =VLOOKUP(B386,Player!C:D,2,FALSE) -> 76 | K386: 69 | L386: 3 | M386: 7.3 | N386: 2.5
A387: Heat | B387: Bam Adebayo | C387: 0 | D387: 8 | E387: 4.3 | F387: Warriors | H387: 69 | J387: =VLOOKUP(B387,Player!C:D,2,FALSE) -> 77 | K387: 69 | L387: 0 | M387: 8 | N387: 4.3
A388: Heat | B388: Jimmy Butler III | C388: 0.6 | D388: 7.5 | E388: 7.4 | F388: Warriors | H388: 69 | J388: =VLOOKUP(B388,Player!C:D,2,FALSE) -> 78 | K388: 69 | L388: 0.6 | M388: 7.5 | N388: 7.4
A389: Heat | B389: Caleb Martin | C389: 1.2 | D389: 3.6 | E389: 1.3 | F389: Warriors | H389: 69 | J389: =VLOOKUP(B389,Player!C:D,2,FALSE) -> 79 | K389: 69 | L389: 1.2 | M389: 3.6 | N389: 1.3
A390: Heat | B390: Max Strus | C390: 2.5 | D390: 4.1 | E390: 1 | F390: Warriors | H390: 69 | J390: =VLOOKUP(B390,Player!C:D,2,FALSE) -> 80 | K390: 69 | L390: 2.5 | M390: 4.1 | N390: 1
A391: Heat | B391: Tyler Herro | C391: 3 | D391: 7.3 | E391: 2.5 | F391: Kings | H391: 81 | J391: =VLOOKUP(B391,Player!C:D,2,FALSE) -> 76 | K391: 81 | L391: 3 | M391: 7.3 | N391: 2.5
A392: Heat | B392: Bam Adebayo | C392: 0 | D392: 8 | E392: 4.3 | F392: Kings | H392: 81 | J392: =VLOOKUP(B392,Player!C:D,2,FALSE) -> 77 | K392: 81 | L392: 0 | M392: 8 | N392: 4.3
... A984: Bucks | B984: Bobby Portis | C984: 1.4 | D984: 5.7 | E984: 1.4 | F984: Pistons | H984: 100 | J984: =VLOOKUP(B984,Player!C:D,2,FALSE) -> 85 | K984: 100 | L984: 1.4 | M984: 5.7 | N984: 1.4

Sheet Game_team_temp
A1: Team 1 | B1: Team 2 | C1: Points Team 1 | D1: Points Team 2 | E1: Winner Team 1 | F1: Winner Team 2
A2: 76ers | B2: Celtics | C2: 117 | D2: 126 | E2: 0 | F2: 1 | G2: 1
A3: Lakers | B3: Warriors | C3: 109 | D3: 123 | E3: 0 | F3: 1 | G3: 2
A4: Magic | B4: Pistons | C4: 109 | D4: 113 | E4: 0 | F4: 1 | G4: 3
A5: Wizards | B5: Pacers | C5: 114 | D5: 107 | E5: 1 | F5: 0 | G5: 4
A6: Cavaliers | B6: Raptors | C6: 105 | D6: 108 | E6: 0 | F6: 1 | G6: 5
A7: Bulls | B7: Heat | C7: 116 | D7: 108 | E7: 0 | F7: 1 | G7: 6
A8: Pelicans | B8: Nets | C8: 130 | D8: 108 | E8: 1 | F8: 0 | G8: 7
A9: Rockets | B9: Hawks | C9: 107 | D9: 117 | E9: 0 | F9: 1 | G9: 8
A10: Knicks | B10: Grizzlies | C10: 112 | D10: 115 | E10: 0 | F10: 1 | G10: 9
A11: Thunder | B11: Timberwolves | C11: 108 | D11: 115 | E11: 0 | F11: 1 | G11: 10
A12: Hornets | B12: Spurs | C12: 129 | D12: 102 | E12: 1 | F12: 0 | G12: 11
A13: Nuggets | B13: Jazz | C13: 102 | D13: 123 | E13: 0 | F13: 1 | G13: 12
... A103: Rockets | B103: Clippers | C103: 93 | D103: 95 | E103: 0 | F103: 1 | G103: 102

Sheet Fault
A1: id | B1: name
A2: 1 | B2: Personal
A3: 2 | B3: Technical
A4: 3 | B4: Unsportsmanlike

Sheet Conference
A1: id | B1: name | C1: division_name
A2: 1 | B2: East | C2: Atlantic | D2: 1
A3: 2 | B3: East | C3: Central | D3: 2
A4: 3 | B4: East | C4: Southeast | D4: 3
A5: 4 | B5: West | C5: Northwest | D5: 4
A6: 5 | B6: West | C6: Pacific | D6: 5
A7: 6 | B7: West | C7: Southwest | D7: 6

Sheet Game
A1: id | B1: date | C1: stadium_id | D1: season_id
A2: 1 | B2: 2024-10-01 | C2: 30 | D2: 1 | F2: 76ers
A3: 2 | B3: 2024-10-01 | C3: 7 | D3: 1 | F3: Lakers
A4: 3 | B4: 2024-10-01 | C4: 15 | D4: 1 | F4: Magic
A5: 4 | B5: 2024-10-01 | C5: 5 | D5: 1 | F5: Wizards
A6: 5 | B6: 2024-10-01 | C6: 20 | D6: 1 | F6: Cavaliers
A7: 6 | B7: 2024-10-01 | C7: 28 | D7: 1 | F7: Bulls
A8: 7 | B8: 2024-10-01 | C8: 22 | D8: 1 | F8: Pelicans
A9: 8 | B9: 2024-10-01 | C9: 27 | D9: 1 | F9: Rockets
A10: 9 | B10: 2024-10-01 | C10: 17 | D10: 1 | F10: Knicks
A11: 10 | B11: 2024-10-01 | C11: 19 | D11: 1 | F11: Thunder
A12: 11 | B12: 2024-10-01 | C12: 23 | D12: 1 | F12: Hornets
A13: 12 | B13: 2024-10-01 | C13: 3 | D13: 1 | F13: Nuggets
... A103: 102 | B103: 2024-10-30 | C103: 27 | D103: 1 | F103: Rockets

Sheet Game_team
A1: id | B1: game_id | C1: team_id | D1: points | E1: winner
A2: 1 | B2: 1 | C2: =VLOOKUP(F2,Team!E:H,4,FALSE) -> 4 | D2: 117 | E2: 0 | F2: 76ers | G2: ="INSERT INTO player_point (id, game_id, team_id, points, winner) VALUES (" & A2 & ", " & B2 & ", " & C2 & ", " & D2 & ", " & E2 & ");" -> INSERT INTO player_point (id, game_id, team_id, points, winner) VALUES (1, 1, 4, 117, 0);
A3: 103 | B3: 1 | C3: =VLOOKUP(F3,Team!E:H,4,FALSE) -> 1 | D3: 126 | E3: 1 | F3: Celtics | G3: ="INSERT INTO player_point (id, game_id, team_id, points, winner) VALUES (" & A3 & ", " & B3 & ", " & C3 & ", " & D3 & ", " & E3 & ");" -> INSERT INTO player_point (id, game_id, team_id, points, winner) VALUES (103, 1, 1, 126, 1);
A4: 2 | B4: 2 | C4: =VLOOKUP(F4,Team!E:H,4,FALSE) -> 23 | D4: 109 | E4: 0 | F4: Lakers | G4: ="INSERT INTO player_point (id, game_id, team_id, points, winner) VALUES (" & A4 & ", " & B4 & ", " & C4 & ", " & D4 & ", " & E4 & ");" -> INSERT INTO player_point (id, game_id, team_id, points, winner) VALUES (2, 2, 23, 109, 0);
A5: 104 | B5: 2 | C5: =VLOOKUP(F5,Team!E:H,4,FALSE) -> 21 | D5: 123 | E5: 1 | F5: Warriors | G5: ="INSERT INTO player_point (id, game_id, team_id, points, winner) VALUES (" & A5 & ", " & B5 & ", " & C5 & ", " & D5 & ", " & E5 & ");" -> INSERT INTO player_point (id, game_id, team_id, points, winner) VALUES (104, 2, 21, 123, 1);
A6: 3 | B6: 3 | C6: =VLOOKUP(F6,Team!E:H,4,FALSE) -> 14 | D6: 109 | E6: 0 | F6: Magic | G6: ="INSERT INTO player_point (id, game_id, team_id, points, winner) VALUES (" & A6 & ", " & B6 & ", " & C6 & ", " & D6 & ", " & E6 & ");" -> INSERT INTO player_point (id, game_id, team_id, points, winner) VALUES (3, 3, 14, 109, 0);
A7: 105 | B7: 3 | C7: =VLOOKUP(F7,Team!E:H,4,FALSE) -> 8 | D7: 113 | E7: 1 | F7: Pistons | G7: ="INSERT INTO player_point (id, game_id, team_id, points, winner) VALUES (" & A7 & ", " & B7 & ", " & C7 & ", " & D7 & ", " & E7 & ");" -> INSERT INTO player_point (id, game_id, team_id, points, winner) VALUES (105, 3, 8, 113, 1);
A8: 4 | B8: 4 | C8: =VLOOKUP(F8,Team!E:H,4,FALSE) -> 15 | D8: 114 | E8: 1 | F8: Wizards | G8: ="INSERT INTO player_point (id, game_id, team_id, points, winner) VALUES (" & A8 & ", " & B8 & ", " & C8 & ", " & D8 & ", " & E8 & ");" -> INSERT INTO player_point (id, game_id, team_id, points, winner) VALUES (4, 4, 15, 114, 1);
A9: 106 | B9: 4 | C9: =VLOOKUP(F9,Team!E:H,4,FALSE) -> 9 | D9: 107 | E9: 0 | F9: Pacers | G9: ="INSERT INTO player_point (id, game_id, team_id, points, winner) VALUES (" & A9 & ", " & B9 & ", " & C9 & ", " & D9 & ", " & E9 & ");" -> INSERT INTO player_point (id, game_id, team_id, points, winner) VALUES (106, 4, 9, 107, 0);
A10: 5 | B10: 5 | C10: =VLOOKUP(F10,Team!E:H,4,FALSE) -> 7 | D10: 105 | E10: 0 | F10: Cavaliers | G10: ="INSERT INTO player_point (id, game_id, team_id, points, winner) VALUES (" & A10 & ", " & B10 & ", " & C10 & ", " & D10 & ", " & E10 & ");" -> INSERT INTO player_point (id, game_id, team_id, points, winner) VALUES (5, 5, 7, 105, 0);
A11: 107 | B11: 5 | C11: =VLOOKUP(F11,Team!E:H,4,FALSE) -> 5 | D11: 108 | E11: 1 | F11: Raptors | G11: ="INSERT INTO player_point (id, game_id, team_id, points, winner) VALUES (" & A11 & ", " & B11 & ", " & C11 & ", " & D11 & ", " & E11 & ");" -> INSERT INTO player_point (id, game_id, team_id, points, winner) VALUES (107, 5, 5, 108, 1);
A12: 6 | B12: 6 | C12: =VLOOKUP(F12,Team!E:H,4,FALSE) -> 6 | D12: 116 | E12: 0 | F12: Bulls | G12: ="INSERT INTO player_point (id, game_id, team_id, points, winner) VALUES (" & A12 & ", " & B12 & ", " & C12 & ", " & D12 & ", " & E12 & ");" -> INSERT INTO player_point (id, game_id, team_id, points, winner) VALUES (6, 6, 6, 116, 0);
A13: 108 | B13: 6 | C13: =VLOOKUP(F13,Team!E:H,4,FALSE) -> 13 | D13: 108 | E13: 1 | F13: Heat | G13: ="INSERT INTO player_point (id, game_id, team_id, points, winner) VALUES (" & A13 & ", " & B13 & ", " & C13 & ", " & D13 & ", " & E13 & ");" -> INSERT INTO player_point (id, game_id, team_id, points, winner) VALUES (108, 6, 13, 108, 1);
... A18: 9 | B18: 9 | C18: =VLOOKUP(F18,Team!E:H,4,FALSE) -> 3 | D18: 112 | E18: 0 | F18: Knicks | G18: ="INSERT INTO player_point (id, game_id, team_id, points, winner) VALUES (" & A18 & ", " & B18 & ", " & C18 & ", " & D18 & ", " & E18 & ");" -> INSERT INTO player_point (id, game_id, team_id, points, winner) VALUES (9, 9, 3, 112, 0);
A19: 111 | B19: 9 | C19: 28 | D19: 115 | E19: 1 | F19: Grizzilies | G19: ="INSERT INTO player_point (id, game_id, team_id, points, winner) VALUES (" & A19 & ", " & B19 & ", " & C19 & ", " & D19 & ", " & E19 & ");" -> INSERT INTO player_point (id, game_id, team_id, points, winner) VALUES (111, 9, 28, 115, 1);
A20: 10 | B20: 10 | C20: =VLOOKUP(F20,Team!E:H,4,FALSE) -> 18 | D20: 108 | E20: 0 | F20: Thunder | G20: ="INSERT INTO player_point (id, game_id, team_id, points, winner) VALUES (" & A20 & ", " & B20 & ", " & C20 & ", " & D20 & ", " & E20 & ");" -> INSERT INTO player_point (id, game_id, team_id, points, winner) VALUES (10, 10, 18, 108, 0);
A21: 112 | B21: 10 | C21: =VLOOKUP(F21,Team!E:H,4,FALSE) -> 17 | D21: 115 | E21: 1 | F21: Timberwolves | G21: ="INSERT INTO player_point (id, game_id, team_id, points, winner) VALUES (" & A21 & ", " & B21 & ", " & C21 & ", " & D21 & ", " & E21 & ");" -> INSERT INTO player_point (id, game_id, team_id, points, winner) VALUES (112, 10, 17, 115, 1);
A22: 11 | B22: 11 | C22: =VLOOKUP(F22,Team!E:H,4,FALSE) -> 12 | D22: 129 | E22: 1 | F22: Hornets | G22: ="INSERT INTO player_point (id, game_id, team_id, points, winner) VALUES (" & A22 & ", " & B22 & ", " & C22 & ", " & D22 & ", " & E22 & ");" -> INSERT INTO player_point (id, game_id, team_id, points, winner) VALUES (11, 11, 12, 129, 1);
A23: 113 | B23: 11 | C23: =VLOOKUP(F23,Team!E:H,4,FALSE) -> 30 | D23: 102 | E23: 0 | F23: Spurs | G23: ="INSERT INTO player_point (id, game_id, team_id, points, winner) VALUES (" & A23 & ", " & B23 & ", " & C23 & ", " & D23 & ", " & E23 & ");" -> INSERT INTO player_point (id, game_id, team_id, points, winner) VALUES (113, 11, 30, 102, 0);
A24: 12 | B24: 12 | C24: =VLOOKUP(F24,Team!E:H,4,FALSE) -> 16 | D24: 102 | E24: 0 | F24: Nuggets | G24: ="INSERT INTO player_point (id, game_id, team_id, points, winner) VALUES (" & A24 & ", " & B24 & ", " & C24 & ", " & D24 & ", " & E24 & ");" -> INSERT INTO player_point (id, game_id, team_id, points, winner) VALUES (12, 12, 16, 102, 0);
A25: 114 | B25: 12 | C25: =VLOOKUP(F25,Team!E:H,4,FALSE) -> 20 | D25: 123 | E25: 1 | F25: Jazz | G25: ="INSERT INTO player_point (id, game_id, team_id, points, winner) VALUES (" & A25 & ", " & B25 & ", " & C25 & ", " & D25 & ", " & E25 & ");" -> INSERT INTO player_point (id, game_id, team_id, points, winner) VALUES (114, 12, 20, 123, 1);
A26: 13 | B26: 13 | C26: =VLOOKUP(F26,Team!E:H,4,FALSE) -> 26 | D26: 105 | E26: 0 | F26: Mavericks | G26: ="INSERT INTO player_point (id, game_id, team_id, points, winner) VALUES (" & A26 & ", " & B26 & ", " & C26 & ", " & D26 & ", " & E26 & ");" -> INSERT INTO player_point (id, game_id, team_id, points, winner) VALUES (13, 13, 26, 105, 0);
A27: 115 | B27: 13 | C27: =VLOOKUP(F27,Team!E:H,4,FALSE) -> 24 | D27: 107 | E27: 1 | F27: Suns | G27: ="INSERT INTO player_point (id, game_id, team_id, points, winner) VALUES (" & A27 & ", " & B27 & ", " & C27 & ", " & D27 & ", " & E27 & ");" -> INSERT INTO player_point (id, game_id, team_id, points, winner) VALUES (115, 13, 24, 107, 1);
A28: 14 | B28: 14 | C28: =VLOOKUP(F28,Team!E:H,4,FALSE) -> 19 | D28: 115 | E28: 1 | F28: Trail Blazers | G28: ="INSERT INTO player_point (id, game_id, team_id, points, winner) VALUES (" & A28 & ", " & B28 & ", " & C28 & ", " & D28 & ", " & E28 & ");" -> INSERT INTO player_point (id, game_id, team_id, points, winner) VALUES (14, 14, 19, 115, 1);
A29: 116 | B29: 14 | C29: =VLOOKUP(F29,Team!E:H,4,FALSE) -> 25 | D29: 108 | E29: 0 | F29: Kings | G29: ="INSERT INTO player_point (id, game_id, team_id, points, winner) VALUES (" & A29 & ", " & B29 & ", " & C29 & ", " & D29 & ", " & E29 & ");" -> INSERT INTO player_point (id, game_id, team_id, points, winner) VALUES (116, 14, 25, 108, 0);
A30: 15 | B30: 15 | C30: =VLOOKUP(F30,Team!E:H,4,FALSE) -> 10 | D30: 90 | E30: 1 | F30: Bucks | G30: ="INSERT INTO player_point (id, game_id, team_id, points, winner) VALUES (" & A30 & ", " & B30 & ", " & C30 & ", " & D30 & ", " & E30 & ");" -> INSERT INTO player_point (id, game_id, team_id, points, winner) VALUES (15, 15, 10, 90, 1);
A31: 117 | B31: 15 | C31: =VLOOKUP(F31,Team!E:H,4,FALSE) -> 4 | D31: 88 | E31: 0 | F31: 76ers | G31: ="INSERT INTO player_point (id, game_id, team_id, points, winner) VALUES (" & A31 & ", " & B31 & ", " & C31 & ", " & D31 & ", " & E31 & ");" -> INSERT INTO player_point (id, game_id, team_id, points, winner) VALUES (117, 15, 4, 88, 0);
... A98: 49 | B98: 49 | C98: =VLOOKUP(F98,Team!E:H,4,FALSE) -> 2 | D98: 124 | E98: 0 | F98: Nets | G98: ="INSERT INTO player_point (id, game_id, team_id, points, winner) VALUES (" & A98 & ", " & B98 & ", " & C98 & ", " & D98 & ", " & E98 & ");" -> INSERT INTO player_point (id, game_id, team_id, points, winner) VALUES (49, 49, 2, 124, 0);
A99: 151 | B99: 49 | C99: 28 | D99: 134 | E99: 1 | F99: Grizzilies | G99: ="INSERT INTO player_point (id, game_id, team_id, points, winner) VALUES (" & A99 & ", " & B99 & ", " & C99 & ", " & D99 & ", " & E99 & ");" -> INSERT INTO player_point (id, game_id, team_id, points, winner) VALUES (151, 49, 28, 134, 1);
A100: 50 | B100: 50 | C100: =VLOOKUP(F100,Team!E:H,4,FALSE) -> 30 | D100: 115 | E100: 1 | F100: Spurs | G100: ="INSERT INTO player_point (id, game_id, team_id, points, winner) VALUES (" & A100 & ", " & B100 & ", " & C100 & ", " & D100 & ", " & E100 & ");" -> INSERT INTO player_point (id, game_id, team_id, points, winner) VALUES (50, 50, 30, 115, 1);
A101: 152 | B101: 50 | C101: =VLOOKUP(F101,Team!E:H,4,FALSE) -> 17 | D101: 106 | E101: 0 | F101: Timberwolves | G101: ="INSERT INTO player_point (id, game_id, team_id, points, winner) VALUES (" & A101 & ", " & B101 & ", " & C101 & ", " & D101 & ", " & E101 & ");" -> INSERT INTO player_point (id, game_id, team_id, points, winner) VALUES (152, 50, 17, 106, 0);
A102: 51 | B102: 51 | C102: =VLOOKUP(F102,Team!E:H,4,FALSE) -> 16 | D102: 110 | E102: 0 | F102: Nuggets | G102: ="INSERT INTO player_point (id, game_id, team_id, points, winner) VALUES (" & A102 & ", " & B102 & ", " & C102 & ", " & D102 & ", " & E102 & ");" -> INSERT INTO player_point (id, game_id, team_id, points, winner) VALUES (51, 51, 16, 110, 0);
A103: 153 | B103: 51 | C103: =VLOOKUP(F103,Team!E:H,4,FALSE) -> 19 | D103: 135 | E103: 1 | F103: Trail Blazers | G103: ="INSERT INTO player_point (id, game_id, team_id, points, winner) VALUES (" & A103 & ", " & B103 & ", " & C103 & ", " & D103 & ", " & E103 & ");" -> INSERT INTO player_point (id, game_id, team_id, points, winner) VALUES (153, 51, 19, 135, 1);
A104: 52 | B104: 52 | C104: =VLOOKUP(F104,Team!E:H,4,FALSE) -> 8 | D104: 99 | E104: 0 | F104: Pistons | G104: ="INSERT INTO player_point (id, game_id, team_id, points, winner) VALUES (" & A104 & ", " & B104 & ", " & C104 & ", " & D104 & ", " & E104 & ");" -> INSERT INTO player_point (id, game_id, team_id, points, winner) VALUES (52, 52, 8, 99, 0);
A105: 154 | B105: 52 | C105: =VLOOKUP(F105,Team!E:H,4,FALSE) -> 15 | D105: 120 | E105: 1 | F105: Wizards | G105: ="INSERT INTO player_point (id, game_id, team_id, points, winner) VALUES (" & A105 & ", " & B105 & ", " & C105 & ", " & D105 & ", " & E105 & ");" -> INSERT INTO player_point (id, game_id, team_id, points, winner) VALUES (154, 52, 15, 120, 1);
A106: 53 | B106: 53 | C106: =VLOOKUP(F106,Team!E:H,4,FALSE) -> 26 | D106: 111 | E106: 0 | F106: Mavericks | G106: ="INSERT INTO player_point (id, game_id, team_id, points, winner) VALUES (" & A106 & ", " & B106 & ", " & C106 & ", " & D106 & ", " & E106 & ");" -> INSERT INTO player_point (id, game_id, team_id, points, winner) VALUES (53, 53, 26, 111, 0);
A107: 155 | B107: 53 | C107: =VLOOKUP(F107,Team!E:H,4,FALSE) -> 29 | D107: 113 | E107: 1 | F107: Pelicans | G107: ="INSERT INTO player_point (id, game_id, team_id, points, winner) VALUES (" & A107 & ", " & B107 & ", " & C107 & ", " & D107 & ", " & E107 & ");" -> INSERT INTO player_point (id, game_id, team_id, points, winner) VALUES (155, 53, 29, 113, 1);
A108: 54 | B108: 54 | C108: =VLOOKUP(F108,Team!E:H,4,FALSE) -> 22 | D108: 94 | E108: 0 | F108: Clippers | G108: ="INSERT INTO player_point (id, game_id, team_id, points, winner) VALUES (" & A108 & ", " & B108 & ", " & C108 & ", " & D108 & ", " & E108 & ");" -> INSERT INTO player_point (id, game_id, team_id, points, winner) VALUES (54, 54, 22, 94, 0);
A109: 156 | B109: 54 | C109: =VLOOKUP(F109,Team!E:H,4,FALSE) -> 18 | D109: 108 | E109: 1 | F109: Thunder | G109: ="INSERT INTO player_point (id, game_id, team_id, points, winner) VALUES (" & A109 & ", " & B109 & ", " & C109 & ", " & D109 & ", " & E109 & ");" -> INSERT INTO player_point (id, game_id, team_id, points, winner) VALUES (156, 54, 18, 108, 1);
A110: 55 | B110: 55 | C110: =VLOOKUP(F110,Team!E:H,4,FALSE) -> 21 | D110: 105 | E110: 0 | F110: Warriors | G110: ="INSERT INTO player_point (id, game_id, team_id, points, winner) VALUES (" & A110 & ", " & B110 & ", " & C110 & ", " & D110 & ", " & E110 & ");" -> INSERT INTO player_point (id, game_id, team_id, points, winner) VALUES (55, 55, 21, 105, 0);
...

Sheet Stadium
A1: id | B1: name | C1: city
A2: 1 | B2: AT&T Center | C2: San Antonio | D2: Spurs | E2: 1
A3: 2 | B3: American Airlines Center | C3: Dallas | D3: Mavericks | E3: 2
A4: 3 | B4: Ball Arena | C4: Denver | D4: Nuggets | E4: 3
A5: 4 | B5: Barclays Center | C5: Brooklyn | D5: Nets | E5: 4
A6: 5 | B6: Capital One Arena | C6: Washington | D6: Wizards | E6: 5
A7: 6 | B7: Chase Center | C7: San Francisco | D7: Warriors | E7: 6
A8: 7 | B8: Crypto.com Arena | C8: Los Angeles | D8: Lakers | E8: 7 | G8: Clippers
A9: 9 | B9: FedExForum | C9: Memphis | D9: Grizzlies | E9: 9
A10: 10 | B10: Fiserv Forum | C10: Milwaukee | D10: Bucks | E10: 10
A11: 11 | B11: Footprint Center | C11: Phoenix | D11: Suns | E11: 11
A12: 12 | B12: Gainbridge Fieldhouse | C12: Indianapolis | D12: Pacers | E12: 12
A13: 13 | B13: Golden 1 Center | C13: Sacramento | D13: Kings | E13: 13
A14: 14 | B14: Kaseya Center | C14: Miami | D14: Heat | E14: 14
A15: 15 | B15: Kia Center | C15: Orlando | D15: Magic | E15: 15
A16: 16 | B16: Little Caesars Arena | C16: Detroit | D16: Pistons | E16: 16
A17: 17 | B17: Madison Square Garden | C17: New York | D17: Knicks | E17: 17
A18: 18 | B18: Moda Center | C18: Portland | D18: Trail Blazers | E18: 18
A19: 19 | B19: Paycom Center | C19: Oklahoma City | D19: Thunder | E19: 19
A20: 20 | B20: Rocket Mortgage FieldHouse | C20: Cleveland | D20: Cavaliers | E20: 20
... A30: 30 | B30: Wells Fargo Center | C30: Philadelphia | D30: 76ers | E30: 30

Sheet Season
A1: id | B1: year | C1: name
A2: 1 | B2: 2022 | C2: October
